Workbook
Name LR: Шаги!$D$8
Name F0: Шаги!$E$16

Sheet Содержание
B2: Градиентный бустинг с learning rate — 20 шагов
B3: Учебное пособие в Excel: один пример (четыре ноутбука), один параметр ν, двадцать шагов — и у каждого числа есть формула, обоснование и живой пересчёт. Жёлтые ячейки — входы; всё остальное считается формулами.
B6: Листы пособия
B8: Теория | C8: Вывод каждой формулы: почему среднее, почему остаток — антиградиент, критерий выбора колонки, learning rate, сходимость, правила остановки.
B9: Сводка | C9: Таблица по 20 шагам с условным форматированием, четыре графика (включая логарифмическую шкалу), ссылки на каждый шаг.
B10: Шаги | C10: Параметры (ν, цены) и 20 сворачиваемых блоков: этапы A–D, у каждой таблицы — живое пояснение с формулой и числами.
B12: Быстрые переходы к шагам
B14: Шаг 1 | C14: ="выбрана колонка: "&Шаги!$E$41&", Σ|rᵢ| после шага = "&TEXT(Шаги!I51,"0.####")
B15: Шаг 2 | C15: ="выбрана колонка: "&Шаги!$E$75&", Σ|rᵢ| после шага = "&TEXT(Шаги!I85,"0.####")
B16: Шаг 3 | C16: ="выбрана колонка: "&Шаги!$E$109&", Σ|rᵢ| после шага = "&TEXT(Шаги!I119,"0.####")
B17: Шаг 4 | C17: ="выбрана колонка: "&Шаги!$E$143&", Σ|rᵢ| после шага = "&TEXT(Шаги!I153,"0.####")
B18: Шаг 5 | C18: ="выбрана колонка: "&Шаги!$E$177&", Σ|rᵢ| после шага = "&TEXT(Шаги!I187,"0.####")
B19: Шаг 6 | C19: ="выбрана колонка: "&Шаги!$E$211&", Σ|rᵢ| после шага = "&TEXT(Шаги!I221,"0.####")
B20: Шаг 7 | C20: ="выбрана колонка: "&Шаги!$E$245&", Σ|rᵢ| после шага = "&TEXT(Шаги!I255,"0.####")
B21: Шаг 8 | C21: ="выбрана колонка: "&Шаги!$E$279&", Σ|rᵢ| после шага = "&TEXT(Шаги!I289,"0.####")
B22: Шаг 9 | C22: ="выбрана колонка: "&Шаги!$E$313&", Σ|rᵢ| после шага = "&TEXT(Шаги!I323,"0.####")
B23: Шаг 10 | C23: ="выбрана колонка: "&Шаги!$E$347&", Σ|rᵢ| после шага = "&TEXT(Шаги!I357,"0.####")
B24: Шаг 11 | C24: ="выбрана колонка: "&Шаги!$E$381&", Σ|rᵢ| после шага = "&TEXT(Шаги!I391,"0.####")
B25: Шаг 12 | C25: ="выбрана колонка: "&Шаги!$E$415&", Σ|rᵢ| после шага = "&TEXT(Шаги!I425,"0.####")
B26: Шаг 13 | C26: ="выбрана колонка: "&Шаги!$E$449&", Σ|rᵢ| после шага = "&TEXT(Шаги!I459,"0.####")
B27: Шаг 14 | C27: ="выбрана колонка: "&Шаги!$E$483&", Σ|rᵢ| после шага = "&TEXT(Шаги!I493,"0.####")
B28: Шаг 15 | C28: ="выбрана колонка: "&Шаги!$E$517&", Σ|rᵢ| после шага = "&TEXT(Шаги!I527,"0.####")
B29: Шаг 16 | C29: ="выбрана колонка: "&Шаги!$E$551&", Σ|rᵢ| после шага = "&TEXT(Шаги!I561,"0.####")
B30: Шаг 17 | C30: ="выбрана колонка: "&Шаги!$E$585&", Σ|rᵢ| после шага = "&TEXT(Шаги!I595,"0.####")
B31: Шаг 18 | C31: ="выбрана колонка: "&Шаги!$E$619&", Σ|rᵢ| после шага = "&TEXT(Шаги!I629,"0.####")
B32: Шаг 19 | C32: ="выбрана колонка: "&Шаги!$E$653&", Σ|rᵢ| после шага = "&TEXT(Шаги!I663,"0.####")
B33: Шаг 20 | C33: ="выбрана колонка: "&Шаги!$E$687&", Σ|rᵢ| после шага = "&TEXT(Шаги!I697,"0.####")
B35: Как пользоваться
B37: • | C37: Жёлтые ячейки на листе «Шаги» — единственные входы: цены четырёх ноутбуков и learning rate ν (проверка: 0.01 ≤ ν ≤ 1).
B38: • | C38: Зелёные ячейки — ключевые результаты этапа. Бежевые строки — пояснения: это формулы, они пересчитываются вместе с таблицами.
B39: • | C39: Кнопки «−/+» слева от строк на листе «Шаги» сворачивают блок шага; кнопки «1/2» над ними — все блоки сразу.
B40: • | C40: Поставьте ν = 1 и убедитесь, что получаются ровно два шага исходного примера; ν = 0.1 — и посмотрите, сколько шагов экран держится в лидерах.

Sheet Теория
B2: Математическое основание каждого расчёта
B3: ← Содержание
B5: 1. Постановка задачи
B6: Есть n = 4 объекта (ноутбуки A, B, C, D) с признаками x (экран, SSD) и целевой переменной y (реальная цена). Строим функцию F(x), прогноз ŷ = F(x), и хотим, чтобы прогноз был как можно ближе к y на всех объектах сразу.
B7: «Как можно ближе» измеряет функция потерь. Здесь — квадратичная: L(y, F) = ½·(y − F)². Она гладкая (есть производная), штрафует большие промахи сильнее малых, и у её минимума простой ответ — среднее (раздел 2).
B9: 2. Шаг 0: почему стартовое предсказание — среднее
B10: Пока признаков не используем, модель — одно число c для всех. Минимизируем сумму квадратов ошибок:
B11: S(c) = Σᵢ (yᵢ − c)² → dS/dc = −2·Σᵢ (yᵢ − c) = 0 → c = (1/n)·Σᵢ yᵢ = ȳ
B12: Производная равна нулю ровно в среднем арифметическом: F₀ = ȳ = (820 + 880 + 1120 + 1180) / 4 = 1000. Это решение задачи минимизации, а не договорённость.
B14: 3. Остаток и его связь с градиентом
B15: Остаток (residual) объекта i на шаге m: rᵢ = yᵢ − F_{m−1}(xᵢ) — насколько текущая модель промахнулась. Минус — завысили, плюс — занизили.
B16: rᵢ = yᵢ − F_{m−1}(xᵢ) = −∂L(yᵢ, F)/∂F при L = ½(y − F)²
... B42: yᵢ — реальная цена (жёлтые ячейки). F_{m−1}(xᵢ) — «Старое предсказание». rᵢ — «Остаток». γ_G — «Поправка (среднее)». h_m(xᵢ) — «Поправка выбранной колонки». ν — «Learning rate». F_m(xᵢ) — «Новое предсказание». Σ|rᵢ| — наглядный индикатор; Σrᵢ² — то, что модель минимизирует на самом деле.

Sheet Шаги
B2: Шаги бустинга 1–20: этапы A → B → C → D с живыми пояснениями
B3: ← Содержание | C3: Сводка и графики → | D3: Теория →
B4: Слева у каждого блока — кнопка «−/+» (группировка строк Excel): шаг можно свернуть. Числа в пояснениях — формулы, они пересчитываются при смене ν или цен.
B6: Параметры и исходные данные
B8: Learning rate ν | D8: 0.5 | E8: 0 < ν ≤ 1. Поставьте 1 — получите исходный пример за 2 шага; 0.1 — очень медленно.
B10: Ноутбук | C10: Экран | D10: SSD | E10: Реальная цена yᵢ
B11: A | C11: 13" | D11: 256 ГБ | E11: 820
B12: B | C12: 13" | D12: 512 ГБ | E12: 880
B13: C | C13: 15" | D13: 256 ГБ | E13: 1120
B14: D | C14: 15" | D14: 512 ГБ | E14: 1180
B16: Стартовое предсказание F₀ = ȳ | E16: =AVERAGE(E11:E14)
B17: ="F₀ = ("&$E$11&" + "&$E$12&" + "&$E$13&" + "&$E$14&") / 4 = "&TEXT($E$16,"0.##")&". Среднее — единственное число, минимизирующее Σ(yᵢ − c)²: dS/dc = −2·Σ(yᵢ − c) = 0 ⇒ c = ȳ (Теория, раздел 2)."
B19: Шаг 1: F_1 = F_0 + ν·h_1
B20: ="Выбрана колонка: "&$E$41&" · Σ|rᵢ|: "&TEXT(F28,"0.##")&" → "&TEXT(I51,"0.##")&" · Σrᵢ²: "&TEXT(G28,"0.##")&" → "&TEXT(J51,"0.##")
B21: A. Остатки текущей модели F_0 (Теория, раздел 3)
B22: ="Остаток — антиградиент квадратичной потери: rᵢ = yᵢ − F_0(xᵢ) = −∂L/∂F — «что модель ещё не выучила». Для A: "&TEXT(D24,"0.##")&" − "&TEXT(C24,"0.##")&" = "&TEXT(E24,"0.##")&"; для B: "&TEXT(D25,"0.##")&" − "&TEXT(C25,"0.##")&" = "&TEXT(E25,"0.##")&"; для C: "&TEXT(D26,"0.##")&" − "&TEXT(C26,"0.##")&" = "&TEXT(E26,"0.##")&"; для D: "&TEXT(D27,"0.##")&" − "&TEXT(C27,"0.##")&" = "&TEXT(E27,"0.##")&". Минус — завысили, плюс — занизили. Σ|rᵢ| = "&TEXT(F28,"0.##")&", Σrᵢ² = "&TEXT(G28,"0.##")&"."
B23: Ноутбук | C23: Старое предсказание F_0(xᵢ) | D23: Реальная yᵢ | E23: Остаток rᵢ = yᵢ − F_0(xᵢ) | F23: |rᵢ|
B24: A | C24: =$E$16 | D24: =$E$11 | E24: =D24-C24 | F24: =ABS(E24)
B25: B | C25: =$E$16 | D25: =$E$12 | E25: =D25-C25 | F25: =ABS(E25)
B26: C | C26: =$E$16 | D26: =$E$13 | E26: =D26-C26 | F26: =ABS(E26)
B27: D | C27: =$E$16 | D27: =$E$14 | E27: =D27-C27 | F27: =ABS(E27)
B28: Σ|rᵢ| и Σrᵢ² | F28: =SUM(F24:F27) | G28: =SUMSQ(E24:E27)
B30: B. Группировка по колонкам и поправки групп (Теория, раздел 4)
B31: ="Группируем по колонке-признаку (он известен у любого нового объекта), а не по остаткам. Лучшее одно число для группы при квадратичной потере — среднее остатков: γ_G = argmin Σ(rᵢ − γ)² = Σrᵢ / |G|. "&"Экран 13″ {A, B}: γ = ("&TEXT(E24,"0.##")&" + "&TEXT(E25,"0.##")&") / 2 = "&TEXT(G33,"0.##")&", остаётся "&TEXT(H33,"0.##")&"; экран 15″ {C, D}: γ = "&TEXT(G34,"0.##")&", остаётся "&TEXT(H34,"0.##")&"; SSD 256 {A, C}: γ = ("&TEXT(E24,"0.##")&" + "&TEXT(E26,"0.##")&") / 2 = "&TEXT(G35,"0.##")&", остаётся "&TEXT(H35,"0.##")&"; SSD 512 {B, D}: γ = "&TEXT(G36,"0.##")&", остаётся "&TEXT(H36,"0.##")&"."
B32: Колонка | C32: Группа G | D32: Состав | E32: Σ остатков группы | F32: |G| | G32: Поправка γ_G = Σrᵢ / |G| | H32: Остаётся Σ(rᵢ − γ_G)²
B33: Экран | C33: 13" | D33: A, B | E33: =E24+E25 | F33: 2 | G33: =E33/F33 | H33: =(E24-G33)^2+(E25-G33)^2
B34: Экран | C34: 15" | D34: C, D | E34: =E26+E27 | F34: 2 | G34: =E34/F34 | H34: =(E26-G34)^2+(E27-G34)^2
B35: SSD | C35: 256 ГБ | D35: A, C | E35: =E24+E26 | F35: 2 | G35: =E35/F35 | H35: =(E24-G35)^2+(E26-G35)^2
B36: SSD | C36: 512 ГБ | D36: B, D | E36: =E25+E27 | F36: 2 | G36: =E36/F36 | H36: =(E25-G36)^2+(E27-G36)^2
B38: C. Выбор колонки: наименьшая оставшаяся сумма квадратов (Теория, раздел 5)
B39: ="Складываем ошибку, оставшуюся в двух группах каждой колонки, и берём минимум. Экран: "&TEXT(H33,"0.##")&" + "&TEXT(H34,"0.##")&" = "&TEXT(C41,"0.##")&"; SSD: "&TEXT(H35,"0.##")&" + "&TEXT(H36,"0.##")&" = "&TEXT(C42,"0.##")&". Меньше у: "&$E$41&IF(MIN(C41:C42)>0," (у соседки в "&TEXT(MAX(C41:C42)/MIN(C41:C42),"0.00")&" раза больше)","")&". Значит h_1 строится по этой колонке, и каждому объекту достаётся γ его группы."
B40: Колонка j | C40: Остаётся Σ(rᵢ − γ)² по обеим группам | D40: Во сколько раз больше минимума | E40: Выбор j* = argmin
B41: Экран | C41: =H33+H34 | D41: =IF(MIN(C41:C42)=0,"—",C41/MIN(C41:C42)) | E41: =IF(C41<=C42,"экран","SSD")
B42: SSD | C42: =H35+H36 | D42: =IF(MIN(C41:C42)=0,"—",C42/MIN(C41:C42))
B44: D. Обновление модели: F_1(xᵢ) = F_0(xᵢ) + ν·h_1(xᵢ) (Теория, раздел 6)
B45: ="Прибавляем не всю поправку, а долю ν = "&TEXT($D$8,"0.00")&". A: F_1(A) = "&TEXT(C47,"0.##")&" + "&TEXT($D$8,"0.00")&" × ("&TEXT(D47,"0.##")&") = "&TEXT(F47,"0.##")&", остаток "&TEXT(G47,"0.##")&" − "&TEXT(F47,"0.##")&" = "&TEXT(H47,"0.##")&"; D: F_1(D) = "&TEXT(C50,"0.##")&" + "&TEXT($D$8,"0.00")&" × ("&TEXT(D50,"0.##")&") = "&TEXT(F50,"0.##")&", остаток "&TEXT(H50,"0.##")&". "&"Итог: Σ|rᵢ| = "&TEXT(I51,"0.##")&" (было "&TEXT(F28,"0.##")&"), Σrᵢ² = "&TEXT(J51,"0.##")&" (было "&TEXT(G28,"0.##")&"). Невыученная часть вклада колонки «"&$E$41&"» умножилась на (1 − ν) = "&TEXT(1-$D$8,"0.00")&": из "&TEXT(MAX(ABS(D47),ABS(D48)),"0.##")&" осталось "&TEXT(MAX(ABS(D47),ABS(D48))*(1-$D$8),"0.##")&" — эта колонка победит снова, только если остаток её вклада больше невыученного вклада другой колонки (Теория, раздел 7)."
B46: Ноутбук | C46: F_{0}(xᵢ) | D46: h_1(xᵢ) — поправка выбранной колонки | E46: ν·h_1(xᵢ) | F46: F_1(xᵢ) = F_{0} + ν·h_1 | G46: yᵢ | H46: Новый остаток yᵢ − F_1(xᵢ) | I46: |остаток| | J46: остаток²
B47: A | C47: =$E$16 | D47: =IF($E$41="экран",G33,G35) | E47: =$D$8*D47 | F47: =C47+E47 | G47: =$E$11 | H47: =G47-F47 | I47: =ABS(H47) | J47: =H47^2
B48: B | C48: =$E$16 | D48: =IF($E$41="экран",G33,G36) | E48: =$D$8*D48 | F48: =C48+E48 | G48: =$E$12 | H48: =G48-F48 | I48: =ABS(H48) | J48: =H48^2
B49: C | C49: =$E$16 | D49: =IF($E$41="экран",G34,G35) | E49: =$D$8*D49 | F49: =C49+E49 | G49: =$E$13 | H49: =G49-F49 | I49: =ABS(H49) | J49: =H49^2
...

Sheet Сводка
B2: Сводка по 20 шагам и графики
B3: ← Содержание | D3: Шаги → | F3: Теория →
B5: Learning rate ν (с листа «Шаги») | E5: =Шаги!$D$8
B6: F₀ = ȳ | E6: =Шаги!$E$16
B8: Шаг | C8: Выбрана колонка | D8: Σ|остатков| | E8: Σ квадратов | F8: Поправки экран {13″; 15″} | G8: Поправки SSD {256; 512} | H8: F(A) | I8: F(B) | J8: F(C) | K8: F(D) | L8: |ν·h| шага
B9: 0 | C9: — (среднее) | D9: =ABS(Шаги!$E$11-Шаги!$E$16)+ABS(Шаги!$E$12-Шаги!$E$16)+ABS(Шаги!$E$13-Шаги!$E$16)+ABS(Шаги!$E$14-Шаги!$E$16) | E9: =(Шаги!$E$11-Шаги!$E$16)^2+(Шаги!$E$12-Шаги!$E$16)^2+(Шаги!$E$13-Шаги!$E$16)^2+(Шаги!$E$14-Шаги!$E$16)^2 | H9: =Шаги!$E$16 | I9: =Шаги!$E$16 | J9: =Шаги!$E$16 | K9: =Шаги!$E$16 | L9: 0
B10: 1 | C10: =Шаги!$E$41 | D10: =Шаги!I51 | E10: =Шаги!J51 | F10: ="{"&TEXT(Шаги!G33,"0.00")&"; "&TEXT(Шаги!G34,"0.00")&"}" | G10: ="{"&TEXT(Шаги!G35,"0.00")&"; "&TEXT(Шаги!G36,"0.00")&"}" | H10: =Шаги!F47 | I10: =Шаги!F48 | J10: =Шаги!F49 | K10: =Шаги!F50 | L10: =MAX(ABS(Шаги!E47),ABS(Шаги!E48))
B11: 2 | C11: =Шаги!$E$75 | D11: =Шаги!I85 | E11: =Шаги!J85 | F11: ="{"&TEXT(Шаги!G67,"0.00")&"; "&TEXT(Шаги!G68,"0.00")&"}" | G11: ="{"&TEXT(Шаги!G69,"0.00")&"; "&TEXT(Шаги!G70,"0.00")&"}" | H11: =Шаги!F81 | I11: =Шаги!F82 | J11: =Шаги!F83 | K11: =Шаги!F84 | L11: =MAX(ABS(Шаги!E81),ABS(Шаги!E82))
B12: 3 | C12: =Шаги!$E$109 | D12: =Шаги!I119 | E12: =Шаги!J119 | F12: ="{"&TEXT(Шаги!G101,"0.00")&"; "&TEXT(Шаги!G102,"0.00")&"}" | G12: ="{"&TEXT(Шаги!G103,"0.00")&"; "&TEXT(Шаги!G104,"0.00")&"}" | H12: =Шаги!F115 | I12: =Шаги!F116 | J12: =Шаги!F117 | K12: =Шаги!F118 | L12: =MAX(ABS(Шаги!E115),ABS(Шаги!E116))
B13: 4 | C13: =Шаги!$E$143 | D13: =Шаги!I153 | E13: =Шаги!J153 | F13: ="{"&TEXT(Шаги!G135,"0.00")&"; "&TEXT(Шаги!G136,"0.00")&"}" | G13: ="{"&TEXT(Шаги!G137,"0.00")&"; "&TEXT(Шаги!G138,"0.00")&"}" | H13: =Шаги!F149 | I13: =Шаги!F150 | J13: =Шаги!F151 | K13: =Шаги!F152 | L13: =MAX(ABS(Шаги!E149),ABS(Шаги!E150))
B14: 5 | C14: =Шаги!$E$177 | D14: =Шаги!I187 | E14: =Шаги!J187 | F14: ="{"&TEXT(Шаги!G169,"0.00")&"; "&TEXT(Шаги!G170,"0.00")&"}" | G14: ="{"&TEXT(Шаги!G171,"0.00")&"; "&TEXT(Шаги!G172,"0.00")&"}" | H14: =Шаги!F183 | I14: =Шаги!F184 | J14: =Шаги!F185 | K14: =Шаги!F186 | L14: =MAX(ABS(Шаги!E183),ABS(Шаги!E184))
B15: 6 | C15: =Шаги!$E$211 | D15: =Шаги!I221 | E15: =Шаги!J221 | F15: ="{"&TEXT(Шаги!G203,"0.00")&"; "&TEXT(Шаги!G204,"0.00")&"}" | G15: ="{"&TEXT(Шаги!G205,"0.00")&"; "&TEXT(Шаги!G206,"0.00")&"}" | H15: =Шаги!F217 | I15: =Шаги!F218 | J15: =Шаги!F219 | K15: =Шаги!F220 | L15: =MAX(ABS(Шаги!E217),ABS(Шаги!E218))
B16: 7 | C16: =Шаги!$E$245 | D16: =Шаги!I255 | E16: =Шаги!J255 | F16: ="{"&TEXT(Шаги!G237,"0.00")&"; "&TEXT(Шаги!G238,"0.00")&"}" | G16: ="{"&TEXT(Шаги!G239,"0.00")&"; "&TEXT(Шаги!G240,"0.00")&"}" | H16: =Шаги!F251 | I16: =Шаги!F252 | J16: =Шаги!F253 | K16: =Шаги!F254 | L16: =MAX(ABS(Шаги!E251),ABS(Шаги!E252))
B17: 8 | C17: =Шаги!$E$279 | D17: =Шаги!I289 | E17: =Шаги!J289 | F17: ="{"&TEXT(Шаги!G271,"0.00")&"; "&TEXT(Шаги!G272,"0.00")&"}" | G17: ="{"&TEXT(Шаги!G273,"0.00")&"; "&TEXT(Шаги!G274,"0.00")&"}" | H17: =Шаги!F285 | I17: =Шаги!F286 | J17: =Шаги!F287 | K17: =Шаги!F288 | L17: =MAX(ABS(Шаги!E285),ABS(Шаги!E286))
B18: 9 | C18: =Шаги!$E$313 | D18: =Шаги!I323 | E18: =Шаги!J323 | F18: ="{"&TEXT(Шаги!G305,"0.00")&"; "&TEXT(Шаги!G306,"0.00")&"}" | G18: ="{"&TEXT(Шаги!G307,"0.00")&"; "&TEXT(Шаги!G308,"0.00")&"}" | H18: =Шаги!F319 | I18: =Шаги!F320 | J18: =Шаги!F321 | K18: =Шаги!F322 | L18: =MAX(ABS(Шаги!E319),ABS(Шаги!E320))
B19: 10 | C19: =Шаги!$E$347 | D19: =Шаги!I357 | E19: =Шаги!J357 | F19: ="{"&TEXT(Шаги!G339,"0.00")&"; "&TEXT(Шаги!G340,"0.00")&"}" | G19: ="{"&TEXT(Шаги!G341,"0.00")&"; "&TEXT(Шаги!G342,"0.00")&"}" | H19: =Шаги!F353 | I19: =Шаги!F354 | J19: =Шаги!F355 | K19: =Шаги!F356 | L19: =MAX(ABS(Шаги!E353),ABS(Шаги!E354))
B20: 11 | C20: =Шаги!$E$381 | D20: =Шаги!I391 | E20: =Шаги!J391 | F20: ="{"&TEXT(Шаги!G373,"0.00")&"; "&TEXT(Шаги!G374,"0.00")&"}" | G20: ="{"&TEXT(Шаги!G375,"0.00")&"; "&TEXT(Шаги!G376,"0.00")&"}" | H20: =Шаги!F387 | I20: =Шаги!F388 | J20: =Шаги!F389 | K20: =Шаги!F390 | L20: =MAX(ABS(Шаги!E387),ABS(Шаги!E388))
B21: 12 | C21: =Шаги!$E$415 | D21: =Шаги!I425 | E21: =Шаги!J425 | F21: ="{"&TEXT(Шаги!G407,"0.00")&"; "&TEXT(Шаги!G408,"0.00")&"}" | G21: ="{"&TEXT(Шаги!G409,"0.00")&"; "&TEXT(Шаги!G410,"0.00")&"}" | H21: =Шаги!F421 | I21: =Шаги!F422 | J21: =Шаги!F423 | K21: =Шаги!F424 | L21: =MAX(ABS(Шаги!E421),ABS(Шаги!E422))
B22: 13 | C22: =Шаги!$E$449 | D22: =Шаги!I459 | E22: =Шаги!J459 | F22: ="{"&TEXT(Шаги!G441,"0.00")&"; "&TEXT(Шаги!G442,"0.00")&"}" | G22: ="{"&TEXT(Шаги!G443,"0.00")&"; "&TEXT(Шаги!G444,"0.00")&"}" | H22: =Шаги!F455 | I22: =Шаги!F456 | J22: =Шаги!F457 | K22: =Шаги!F458 | L22: =MAX(ABS(Шаги!E455),ABS(Шаги!E456))
B23: 14 | C23: =Шаги!$E$483 | D23: =Шаги!I493 | E23: =Шаги!J493 | F23: ="{"&TEXT(Шаги!G475,"0.00")&"; "&TEXT(Шаги!G476,"0.00")&"}" | G23: ="{"&TEXT(Шаги!G477,"0.00")&"; "&TEXT(Шаги!G478,"0.00")&"}" | H23: =Шаги!F489 | I23: =Шаги!F490 | J23: =Шаги!F491 | K23: =Шаги!F492 | L23: =MAX(ABS(Шаги!E489),ABS(Шаги!E490))
B24: 15 | C24: =Шаги!$E$517 | D24: =Шаги!I527 | E24: =Шаги!J527 | F24: ="{"&TEXT(Шаги!G509,"0.00")&"; "&TEXT(Шаги!G510,"0.00")&"}" | G24: ="{"&TEXT(Шаги!G511,"0.00")&"; "&TEXT(Шаги!G512,"0.00")&"}" | H24: =Шаги!F523 | I24: =Шаги!F524 | J24: =Шаги!F525 | K24: =Шаги!F526 | L24: =MAX(ABS(Шаги!E523),ABS(Шаги!E524))
B25: 16 | C25: =Шаги!$E$551 | D25: =Шаги!I561 | E25: =Шаги!J561 | F25: ="{"&TEXT(Шаги!G543,"0.00")&"; "&TEXT(Шаги!G544,"0.00")&"}" | G25: ="{"&TEXT(Шаги!G545,"0.00")&"; "&TEXT(Шаги!G546,"0.00")&"}" | H25: =Шаги!F557 | I25: =Шаги!F558 | J25: =Шаги!F559 | K25: =Шаги!F560 | L25: =MAX(ABS(Шаги!E557),ABS(Шаги!E558))
B26: 17 | C26: =Шаги!$E$585 | D26: =Шаги!I595 | E26: =Шаги!J595 | F26: ="{"&TEXT(Шаги!G577,"0.00")&"; "&TEXT(Шаги!G578,"0.00")&"}" | G26: ="{"&TEXT(Шаги!G579,"0.00")&"; "&TEXT(Шаги!G580,"0.00")&"}" | H26: =Шаги!F591 | I26: =Шаги!F592 | J26: =Шаги!F593 | K26: =Шаги!F594 | L26: =MAX(ABS(Шаги!E591),ABS(Шаги!E592))
B27: 18 | C27: =Шаги!$E$619 | D27: =Шаги!I629 | E27: =Шаги!J629 | F27: ="{"&TEXT(Шаги!G611,"0.00")&"; "&TEXT(Шаги!G612,"0.00")&"}" | G27: ="{"&TEXT(Шаги!G613,"0.00")&"; "&TEXT(Шаги!G614,"0.00")&"}" | H27: =Шаги!F625 | I27: =Шаги!F626 | J27: =Шаги!F627 | K27: =Шаги!F628 | L27: =MAX(ABS(Шаги!E625),ABS(Шаги!E626))
B28: 19 | C28: =Шаги!$E$653 | D28: =Шаги!I663 | E28: =Шаги!J663 | F28: ="{"&TEXT(Шаги!G645,"0.00")&"; "&TEXT(Шаги!G646,"0.00")&"}" | G28: ="{"&TEXT(Шаги!G647,"0.00")&"; "&TEXT(Шаги!G648,"0.00")&"}" | H28: =Шаги!F659 | I28: =Шаги!F660 | J28: =Шаги!F661 | K28: =Шаги!F662 | L28: =MAX(ABS(Шаги!E659),ABS(Шаги!E660))
B29: 20 | C29: =Шаги!$E$687 | D29: =Шаги!I697 | E29: =Шаги!J697 | F29: ="{"&TEXT(Шаги!G679,"0.00")&"; "&TEXT(Шаги!G680,"0.00")&"}" | G29: ="{"&TEXT(Шаги!G681,"0.00")&"; "&TEXT(Шаги!G682,"0.00")&"}" | H29: =Шаги!F693 | I29: =Шаги!F694 | J29: =Шаги!F695 | K29: =Шаги!F696 | L29: =MAX(ABS(Шаги!E693),ABS(Шаги!E694))
B31: ="Читать так: колонка побеждает, пока её невыученный вклад больше вклада соседки. С ν = "&TEXT(Шаги!$D$8,"0.00")&" экран держится первые шаги, затем колонки чередуются, и Σ|rᵢ| убывает геометрически — в логарифмической шкале это прямая линия. Цвет в столбце «Выбрана колонка»: синий — экран, оранжевый — SSD; полоски — величина ошибки и размер поправки."
